Workbook
Name pt: Jan!$I$19

Sheet Year
A2: Year : | B2: 2026

Sheet Sheet1
A1: Analyst Name: | B1: Deloitte Email ID: | C1: Module: | D1: Location: | E1: PTO Type: | F1: From Date: | G1: To Date: | H1: Reason of PTO: | I1: Status: | J1: PTO Count | K1: Email Status | L1: Approver | M1: Active/Inactive
A2: Nitish Kumar | B2: =_xlfn.XLOOKUP(Christus_Emp_Table[[#This Row],[Analyst Name:]],[1]!Table1[Analyst Name],[1]!Table1[Deloitte Email ID]) -> #REF! | C2: =_xlfn.XLOOKUP(Christus_Emp_Table[[#This Row],[Analyst Name:]],[1]!Table1[Analyst Name],[1]!Table1[Module]) -> #REF! | D2: =_xlfn.XLOOKUP(Christus_Emp_Table[[#This Row],[Analyst Name:]],[1]!Table1[Analyst Name],[1]!Table1[Location]) -> #REF! | E2: PTO | F2: 45663 | G2: 45663 | H2: PTO | I2: Approved | J2: =NETWORKDAYS(Christus_Emp_Table[[#This Row],[From Date:]],Christus_Emp_Table[[#This Row],[To Date:]]) -> 1 | L2: =_xlfn.XLOOKUP(Christus_Emp_Table[[#This Row],[Analyst Name:]],[1]!Table1[Analyst Name],[1]!Table1[Lead]) -> #REF! | M2: =_xlfn.XLOOKUP(Christus_Emp_Table[[#This Row],[Analyst Name:]],[1]!Table1[Analyst Name],[1]!Table1[Active/Inactive]) -> #REF!
A3: Sruthi G | B3: =_xlfn.XLOOKUP(Christus_Emp_Table[[#This Row],[Analyst Name:]],[1]!Table1[Analyst Name],[1]!Table1[Deloitte Email ID]) -> #REF! | C3: =_xlfn.XLOOKUP(Christus_Emp_Table[[#This Row],[Analyst Name:]],[1]!Table1[Analyst Name],[1]!Table1[Module]) -> #REF! | D3: =_xlfn.XLOOKUP(Christus_Emp_Table[[#This Row],[Analyst Name:]],[1]!Table1[Analyst Name],[1]!Table1[Location]) -> #REF! | E3: PTO | F3: 45670 | G3: 45673 | H3: PTO | I3: Approved | J3: =NETWORKDAYS(Christus_Emp_Table[[#This Row],[From Date:]],Christus_Emp_Table[[#This Row],[To Date:]]) -> 4 | L3: =_xlfn.XLOOKUP(Christus_Emp_Table[[#This Row],[Analyst Name:]],[1]!Table1[Analyst Name],[1]!Table1[Lead]) -> #REF! | M3: =_xlfn.XLOOKUP(Christus_Emp_Table[[#This Row],[Analyst Name:]],[1]!Table1[Analyst Name],[1]!Table1[Active/Inactive]) -> #REF!
A4: Sruthi G | B4: =_xlfn.XLOOKUP(Christus_Emp_Table[[#This Row],[Analyst Name:]],[1]!Table1[Analyst Name],[1]!Table1[Deloitte Email ID]) -> #REF! | C4: =_xlfn.XLOOKUP(Christus_Emp_Table[[#This Row],[Analyst Name:]],[1]!Table1[Analyst Name],[1]!Table1[Module]) -> #REF! | D4: =_xlfn.XLOOKUP(Christus_Emp_Table[[#This Row],[Analyst Name:]],[1]!Table1[Analyst Name],[1]!Table1[Location]) -> #REF! | E4: PTO | F4: 45677 | G4: 45677 | H4: PTO | I4: Approved | J4: =NETWORKDAYS(Christus_Emp_Table[[#This Row],[From Date:]],Christus_Emp_Table[[#This Row],[To Date:]]) -> 1 | L4: =_xlfn.XLOOKUP(Christus_Emp_Table[[#This Row],[Analyst Name:]],[1]!Table1[Analyst Name],[1]!Table1[Lead]) -> #REF! | M4: =_xlfn.XLOOKUP(Christus_Emp_Table[[#This Row],[Analyst Name:]],[1]!Table1[Analyst Name],[1]!Table1[Active/Inactive]) -> #REF!
A5: Anusree Saha | B5: =_xlfn.XLOOKUP(Christus_Emp_Table[[#This Row],[Analyst Name:]],[1]!Table1[Analyst Name],[1]!Table1[Deloitte Email ID]) -> #REF! | C5: =_xlfn.XLOOKUP(Christus_Emp_Table[[#This Row],[Analyst Name:]],[1]!Table1[Analyst Name],[1]!Table1[Module]) -> #REF! | D5: =_xlfn.XLOOKUP(Christus_Emp_Table[[#This Row],[Analyst Name:]],[1]!Table1[Analyst Name],[1]!Table1[Location]) -> #REF! | E5: PTO | F5: 45670 | G5: 45670 | H5: PTO | I5: Approved | J5: =NETWORKDAYS(Christus_Emp_Table[[#This Row],[From Date:]],Christus_Emp_Table[[#This Row],[To Date:]]) -> 1 | L5: =_xlfn.XLOOKUP(Christus_Emp_Table[[#This Row],[Analyst Name:]],[1]!Table1[Analyst Name],[1]!Table1[Lead]) -> #REF! | M5: =_xlfn.XLOOKUP(Christus_Emp_Table[[#This Row],[Analyst Name:]],[1]!Table1[Analyst Name],[1]!Table1[Active/Inactive]) -> #REF!
A6: Anusree Saha | B6: =_xlfn.XLOOKUP(Christus_Emp_Table[[#This Row],[Analyst Name:]],[1]!Table1[Analyst Name],[1]!Table1[Deloitte Email ID]) -> #REF! | C6: =_xlfn.XLOOKUP(Christus_Emp_Table[[#This Row],[Analyst Name:]],[1]!Table1[Analyst Name],[1]!Table1[Module]) -> #REF! | D6: =_xlfn.XLOOKUP(Christus_Emp_Table[[#This Row],[Analyst Name:]],[1]!Table1[Analyst Name],[1]!Table1[Location]) -> #REF! | E6: Emergency | F6: 45688 | G6: 45688 | H6: Sick Leave | I6: Approved | J6: =NETWORKDAYS(Christus_Emp_Table[[#This Row],[From Date:]],Christus_Emp_Table[[#This Row],[To Date:]]) -> 1 | L6: =_xlfn.XLOOKUP(Christus_Emp_Table[[#This Row],[Analyst Name:]],[1]!Table1[Analyst Name],[1]!Table1[Lead]) -> #REF! | M6: =_xlfn.XLOOKUP(Christus_Emp_Table[[#This Row],[Analyst Name:]],[1]!Table1[Analyst Name],[1]!Table1[Active/Inactive]) -> #REF!
A7: Akshaya Kumar | B7: =_xlfn.XLOOKUP(Christus_Emp_Table[[#This Row],[Analyst Name:]],[1]!Table1[Analyst Name],[1]!Table1[Deloitte Email ID]) -> #REF! | C7: =_xlfn.XLOOKUP(Christus_Emp_Table[[#This Row],[Analyst Name:]],[1]!Table1[Analyst Name],[1]!Table1[Module]) -> #REF! | D7: =_xlfn.XLOOKUP(Christus_Emp_Table[[#This Row],[Analyst Name:]],[1]!Table1[Analyst Name],[1]!Table1[Location]) -> #REF! | E7: Emergency | F7: 45688 | G7: 45688 | H7: Sick Leave | I7: Approved | J7: =NETWORKDAYS(Christus_Emp_Table[[#This Row],[From Date:]],Christus_Emp_Table[[#This Row],[To Date:]]) -> 1 | L7: =_xlfn.XLOOKUP(Christus_Emp_Table[[#This Row],[Analyst Name:]],[1]!Table1[Analyst Name],[1]!Table1[Lead]) -> #REF! | M7: =_xlfn.XLOOKUP(Christus_Emp_Table[[#This Row],[Analyst Name:]],[1]!Table1[Analyst Name],[1]!Table1[Active/Inactive]) -> #REF!
A8: Rajitha D | B8: =_xlfn.XLOOKUP(Christus_Emp_Table[[#This Row],[Analyst Name:]],[1]!Table1[Analyst Name],[1]!Table1[Deloitte Email ID]) -> #REF! | C8: =_xlfn.XLOOKUP(Christus_Emp_Table[[#This Row],[Analyst Name:]],[1]!Table1[Analyst Name],[1]!Table1[Module]) -> #REF! | D8: =_xlfn.XLOOKUP(Christus_Emp_Table[[#This Row],[Analyst Name:]],[1]!Table1[Analyst Name],[1]!Table1[Location]) -> #REF! | E8: PTO | F8: 45663 | G8: 45663 | H8: PTO | I8: Approved | J8: =NETWORKDAYS(Christus_Emp_Table[[#This Row],[From Date:]],Christus_Emp_Table[[#This Row],[To Date:]]) -> 1 | L8: =_xlfn.XLOOKUP(Christus_Emp_Table[[#This Row],[Analyst Name:]],[1]!Table1[Analyst Name],[1]!Table1[Lead]) -> #REF! | M8: =_xlfn.XLOOKUP(Christus_Emp_Table[[#This Row],[Analyst Name:]],[1]!Table1[Analyst Name],[1]!Table1[Active/Inactive]) -> #REF!
A9: Rajitha D | B9: =_xlfn.XLOOKUP(Christus_Emp_Table[[#This Row],[Analyst Name:]],[1]!Table1[Analyst Name],[1]!Table1[Deloitte Email ID]) -> #REF! | C9: =_xlfn.XLOOKUP(Christus_Emp_Table[[#This Row],[Analyst Name:]],[1]!Table1[Analyst Name],[1]!Table1[Module]) -> #REF! | D9: =_xlfn.XLOOKUP(Christus_Emp_Table[[#This Row],[Analyst Name:]],[1]!Table1[Analyst Name],[1]!Table1[Location]) -> #REF! | E9: Half Day | F9: 45665 | G9: 45665 | H9: PTO | I9: Approved | J9: =NETWORKDAYS(Christus_Emp_Table[[#This Row],[From Date:]],Christus_Emp_Table[[#This Row],[To Date:]]) -> 1 | L9: =_xlfn.XLOOKUP(Christus_Emp_Table[[#This Row],[Analyst Name:]],[1]!Table1[Analyst Name],[1]!Table1[Lead]) -> #REF! | M9: =_xlfn.XLOOKUP(Christus_Emp_Table[[#This Row],[Analyst Name:]],[1]!Table1[Analyst Name],[1]!Table1[Active/Inactive]) -> #REF!
A10: Rajitha D | B10: =_xlfn.XLOOKUP(Christus_Emp_Table[[#This Row],[Analyst Name:]],[1]!Table1[Analyst Name],[1]!Table1[Deloitte Email ID]) -> #REF! | C10: =_xlfn.XLOOKUP(Christus_Emp_Table[[#This Row],[Analyst Name:]],[1]!Table1[Analyst Name],[1]!Table1[Module]) -> #REF! | D10: =_xlfn.XLOOKUP(Christus_Emp_Table[[#This Row],[Analyst Name:]],[1]!Table1[Analyst Name],[1]!Table1[Location]) -> #REF! | E10: Emergency | F10: 45685 | G10: 45685 | H10: Sick Leave | I10: Approved | J10: =NETWORKDAYS(Christus_Emp_Table[[#This Row],[From Date:]],Christus_Emp_Table[[#This Row],[To Date:]]) -> 1 | L10: =_xlfn.XLOOKUP(Christus_Emp_Table[[#This Row],[Analyst Name:]],[1]!Table1[Analyst Name],[1]!Table1[Lead]) -> #REF! | M10: =_xlfn.XLOOKUP(Christus_Emp_Table[[#This Row],[Analyst Name:]],[1]!Table1[Analyst Name],[1]!Table1[Active/Inactive]) -> #REF!
A11: Pragati Rawat | B11: =_xlfn.XLOOKUP(Christus_Emp_Table[[#This Row],[Analyst Name:]],[1]!Table1[Analyst Name],[1]!Table1[Deloitte Email ID]) -> #REF! | C11: =_xlfn.XLOOKUP(Christus_Emp_Table[[#This Row],[Analyst Name:]],[1]!Table1[Analyst Name],[1]!Table1[Module]) -> #REF! | D11: =_xlfn.XLOOKUP(Christus_Emp_Table[[#This Row],[Analyst Name:]],[1]!Table1[Analyst Name],[1]!Table1[Location]) -> #REF! | E11: PTO | F11: 45659 | G11: 45660 | H11: PTO | I11: Approved | J11: =NETWORKDAYS(Christus_Emp_Table[[#This Row],[From Date:]],Christus_Emp_Table[[#This Row],[To Date:]]) -> 2 | L11: =_xlfn.XLOOKUP(Christus_Emp_Table[[#This Row],[Analyst Name:]],[1]!Table1[Analyst Name],[1]!Table1[Lead]) -> #REF! | M11: =_xlfn.XLOOKUP(Christus_Emp_Table[[#This Row],[Analyst Name:]],[1]!Table1[Analyst Name],[1]!Table1[Active/Inactive]) -> #REF!
A12: Pragati Rawat | B12: =_xlfn.XLOOKUP(Christus_Emp_Table[[#This Row],[Analyst Name:]],[1]!Table1[Analyst Name],[1]!Table1[Deloitte Email ID]) -> #REF! | C12: =_xlfn.XLOOKUP(Christus_Emp_Table[[#This Row],[Analyst Name:]],[1]!Table1[Analyst Name],[1]!Table1[Module]) -> #REF! | D12: =_xlfn.XLOOKUP(Christus_Emp_Table[[#This Row],[Analyst Name:]],[1]!Table1[Analyst Name],[1]!Table1[Location]) -> #REF! | E12: Emergency | F12: 45666 | G12: 45666 | H12: Sick Leave | I12: Approved | J12: =NETWORKDAYS(Christus_Emp_Table[[#This Row],[From Date:]],Christus_Emp_Table[[#This Row],[To Date:]]) -> 1 | L12: =_xlfn.XLOOKUP(Christus_Emp_Table[[#This Row],[Analyst Name:]],[1]!Table1[Analyst Name],[1]!Table1[Lead]) -> #REF! | M12: =_xlfn.XLOOKUP(Christus_Emp_Table[[#This Row],[Analyst Name:]],[1]!Table1[Analyst Name],[1]!Table1[Active/Inactive]) -> #REF!
A13: Ankita Roy | B13: =_xlfn.XLOOKUP(Christus_Emp_Table[[#This Row],[Analyst Name:]],[1]!Table1[Analyst Name],[1]!Table1[Deloitte Email ID]) -> #REF! | C13: =_xlfn.XLOOKUP(Christus_Emp_Table[[#This Row],[Analyst Name:]],[1]!Table1[Analyst Name],[1]!Table1[Module]) -> #REF! | D13: =_xlfn.XLOOKUP(Christus_Emp_Table[[#This Row],[Analyst Name:]],[1]!Table1[Analyst Name],[1]!Table1[Location]) -> #REF! | E13: Emergency | F13: 45664 | G13: 45664 | H13: Sick Leave | I13: Approved | J13: =NETWORKDAYS(Christus_Emp_Table[[#This Row],[From Date:]],Christus_Emp_Table[[#This Row],[To Date:]]) -> 1 | L13: =_xlfn.XLOOKUP(Christus_Emp_Table[[#This Row],[Analyst Name:]],[1]!Table1[Analyst Name],[1]!Table1[Lead]) -> #REF! | M13: =_xlfn.XLOOKUP(Christus_Emp_Table[[#This Row],[Analyst Name:]],[1]!Table1[Analyst Name],[1]!Table1[Active/Inactive]) -> #REF!
... A328: Nitish Kumar | B328: =_xlfn.XLOOKUP(Christus_Emp_Table[[#This Row],[Analyst Name:]],[1]!Table1[Analyst Name],[1]!Table1[Deloitte Email ID]) -> #REF! | C328: =_xlfn.XLOOKUP(Christus_Emp_Table[[#This Row],[Analyst Name:]],[1]!Table1[Analyst Name],[1]!Table1[Module]) -> #REF! | D328: =_xlfn.XLOOKUP(Christus_Emp_Table[[#This Row],[Analyst Name:]],[1]!Table1[Analyst Name],[1]!Table1[Location]) -> #REF! | E328: PTO | F328: 46001 | G328: 46001 | H328: PTO | I328: Approved | J328: =NETWORKDAYS(Christus_Emp_Table[[#This Row],[From Date:]],Christus_Emp_Table[[#This Row],[To Date:]]) -> 1 | L328: =_xlfn.XLOOKUP(Christus_Emp_Table[[#This Row],[Analyst Name:]],[1]!Table1[Analyst Name],[1]!Table1[Lead]) -> #REF! | M328: =_xlfn.XLOOKUP(Christus_Emp_Table[[#This Row],[Analyst Name:]],[1]!Table1[Analyst Name],[1]!Table1[Active/Inactive]) -> #REF!
A329: Nitish Kumar | B329: =_xlfn.XLOOKUP(Christus_Emp_Table[[#This Row],[Analyst Name:]],[1]!Table1[Analyst Name],[1]!Table1[Deloitte Email ID]) -> #REF! | C329: =_xlfn.XLOOKUP(Christus_Emp_Table[[#This Row],[Analyst Name:]],[1]!Table1[Analyst Name],[1]!Table1[Module]) -> #REF! | D329: =_xlfn.XLOOKUP(Christus_Emp_Table[[#This Row],[Analyst Name:]],[1]!Table1[Analyst Name],[1]!Table1[Location]) -> #REF! | E329: PTO | F329: 45954 | G329: 45954 | H329: PTO | I329: Approved | J329: 1 | L329: =_xlfn.XLOOKUP(Christus_Emp_Table[[#This Row],[Analyst Name:]],[1]!Table1[Analyst Name],[1]!Table1[Lead]) -> #REF! | M329: =_xlfn.XLOOKUP(Christus_Emp_Table[[#This Row],[Analyst Name:]],[1]!Table1[Analyst Name],[1]!Table1[Active/Inactive]) -> #REF!
A330: Nitish Kumar | B330: =_xlfn.XLOOKUP(Christus_Emp_Table[[#This Row],[Analyst Name:]],[1]!Table1[Analyst Name],[1]!Table1[Deloitte Email ID]) -> #REF! | C330: =_xlfn.XLOOKUP(Christus_Emp_Table[[#This Row],[Analyst Name:]],[1]!Table1[Analyst Name],[1]!Table1[Module]) -> #REF! | D330: =_xlfn.XLOOKUP(Christus_Emp_Table[[#This Row],[Analyst Name:]],[1]!Table1[Analyst Name],[1]!Table1[Location]) -> #REF! | E330: Emergency | F330: 45787 | G330: 45787 | H330: Sick Leave | I330: Approved | J330: =NETWORKDAYS(Christus_Emp_Table[[#This Row],[From Date:]],Christus_Emp_Table[[#This Row],[To Date:]]) -> 0 | L330: =_xlfn.XLOOKUP(Christus_Emp_Table[[#This Row],[Analyst Name:]],[1]!Table1[Analyst Name],[1]!Table1[Lead]) -> #REF! | M330: =_xlfn.XLOOKUP(Christus_Emp_Table[[#This Row],[Analyst Name:]],[1]!Table1[Analyst Name],[1]!Table1[Active/Inactive]) -> #REF!
A331: Bharti Kumari | B331: =_xlfn.XLOOKUP(Christus_Emp_Table[[#This Row],[Analyst Name:]],[1]!Table1[Analyst Name],[1]!Table1[Deloitte Email ID]) -> #REF! | C331: =_xlfn.XLOOKUP(Christus_Emp_Table[[#This Row],[Analyst Name:]],[1]!Table1[Analyst Name],[1]!Table1[Module]) -> #REF! | D331: =_xlfn.XLOOKUP(Christus_Emp_Table[[#This Row],[Analyst Name:]],[1]!Table1[Analyst Name],[1]!Table1[Location]) -> #REF! | E331: Emergency | F331: 45993 | G331: 45993 | H331: Sick Leave | I331: Approved | J331: =NETWORKDAYS(Christus_Emp_Table[[#This Row],[From Date:]],Christus_Emp_Table[[#This Row],[To Date:]]) -> 1 | L331: =_xlfn.XLOOKUP(Christus_Emp_Table[[#This Row],[Analyst Name:]],[1]!Table1[Analyst Name],[1]!Table1[Lead]) -> #REF! | M331: =_xlfn.XLOOKUP(Christus_Emp_Table[[#This Row],[Analyst Name:]],[1]!Table1[Analyst Name],[1]!Table1[Active/Inactive]) -> #REF!
A332: Jagannath Belel | B332: =_xlfn.XLOOKUP(Christus_Emp_Table[[#This Row],[Analyst Name:]],[1]!Table1[Analyst Name],[1]!Table1[Deloitte Email ID]) -> #REF! | C332: =_xlfn.XLOOKUP(Christus_Emp_Table[[#This Row],[Analyst Name:]],[1]!Table1[Analyst Name],[1]!Table1[Module]) -> #REF! | D332: =_xlfn.XLOOKUP(Christus_Emp_Table[[#This Row],[Analyst Name:]],[1]!Table1[Analyst Name],[1]!Table1[Location]) -> #REF! | E332: PTO | F332: 45999 | G332: 45999 | H332: PTO | I332: Approved | J332: =NETWORKDAYS(Christus_Emp_Table[[#This Row],[From Date:]],Christus_Emp_Table[[#This Row],[To Date:]]) -> 1 | L332: =_xlfn.XLOOKUP(Christus_Emp_Table[[#This Row],[Analyst Name:]],[1]!Table1[Analyst Name],[1]!Table1[Lead]) -> #REF! | M332: =_xlfn.XLOOKUP(Christus_Emp_Table[[#This Row],[Analyst Name:]],[1]!Table1[Analyst Name],[1]!Table1[Active/Inactive]) -> #REF!
A333: Friendsis Rai | B333: =_xlfn.XLOOKUP(Christus_Emp_Table[[#This Row],[Analyst Name:]],[1]!Table1[Analyst Name],[1]!Table1[Deloitte Email ID]) -> #REF! | C333: =_xlfn.XLOOKUP(Christus_Emp_Table[[#This Row],[Analyst Name:]],[1]!Table1[Analyst Name],[1]!Table1[Module]) -> #REF! | D333: =_xlfn.XLOOKUP(Christus_Emp_Table[[#This Row],[Analyst Name:]],[1]!Table1[Analyst Name],[1]!Table1[Location]) -> #REF! | E333: PTO | F333: 46013 | G333: 46015 | H333: PTO | I333: Approved | J333: =NETWORKDAYS(Christus_Emp_Table[[#This Row],[From Date:]],Christus_Emp_Table[[#This Row],[To Date:]]) -> 3 | L333: =_xlfn.XLOOKUP(Christus_Emp_Table[[#This Row],[Analyst Name:]],[1]!Table1[Analyst Name],[1]!Table1[Lead]) -> #REF! | M333: =_xlfn.XLOOKUP(Christus_Emp_Table[[#This Row],[Analyst Name:]],[1]!Table1[Analyst Name],[1]!Table1[Active/Inactive]) -> #REF!
A334: Parth Zalavadia | B334: =_xlfn.XLOOKUP(Christus_Emp_Table[[#This Row],[Analyst Name:]],[1]!Table1[Analyst Name],[1]!Table1[Deloitte Email ID]) -> #REF! | C334: =_xlfn.XLOOKUP(Christus_Emp_Table[[#This Row],[Analyst Name:]],[1]!Table1[Analyst Name],[1]!Table1[Module]) -> #REF! | D334: =_xlfn.XLOOKUP(Christus_Emp_Table[[#This Row],[Analyst Name:]],[1]!Table1[Analyst Name],[1]!Table1[Location]) -> #REF! | E334: PTO | F334: 46013 | G334: 46015 | H334: PTO | I334: Approved | J334: =NETWORKDAYS(Christus_Emp_Table[[#This Row],[From Date:]],Christus_Emp_Table[[#This Row],[To Date:]]) -> 3 | L334: =_xlfn.XLOOKUP(Christus_Emp_Table[[#This Row],[Analyst Name:]],[1]!Table1[Analyst Name],[1]!Table1[Lead]) -> #REF! | M334: =_xlfn.XLOOKUP(Christus_Emp_Table[[#This Row],[Analyst Name:]],[1]!Table1[Analyst Name],[1]!Table1[Active/Inactive]) -> #REF!
A335: Ujjwal waikar | B335: =_xlfn.XLOOKUP(Christus_Emp_Table[[#This Row],[Analyst Name:]],[1]!Table1[Analyst Name],[1]!Table1[Deloitte Email ID]) -> #REF! | C335: =_xlfn.XLOOKUP(Christus_Emp_Table[[#This Row],[Analyst Name:]],[1]!Table1[Analyst Name],[1]!Table1[Module]) -> #REF! | D335: =_xlfn.XLOOKUP(Christus_Emp_Table[[#This Row],[Analyst Name:]],[1]!Table1[Analyst Name],[1]!Table1[Location]) -> #REF! | E335: PTO | F335: 46013 | G335: 46015 | H335: PTO | I335: Approved | J335: =NETWORKDAYS(Christus_Emp_Table[[#This Row],[From Date:]],Christus_Emp_Table[[#This Row],[To Date:]]) -> 3 | L335: =_xlfn.XLOOKUP(Christus_Emp_Table[[#This Row],[Analyst Name:]],[1]!Table1[Analyst Name],[1]!Table1[Lead]) -> #REF! | M335: =_xlfn.XLOOKUP(Christus_Emp_Table[[#This Row],[Analyst Name:]],[1]!Table1[Analyst Name],[1]!Table1[Active/Inactive]) -> #REF!
A336: Robin babu | B336: =_xlfn.XLOOKUP(Christus_Emp_Table[[#This Row],[Analyst Name:]],[1]!Table1[Analyst Name],[1]!Table1[Deloitte Email ID]) -> #REF! | C336: =_xlfn.XLOOKUP(Christus_Emp_Table[[#This Row],[Analyst Name:]],[1]!Table1[Analyst Name],[1]!Table1[Module]) -> #REF! | D336: =_xlfn.XLOOKUP(Christus_Emp_Table[[#This Row],[Analyst Name:]],[1]!Table1[Analyst Name],[1]!Table1[Location]) -> #REF! | E336: PTO | F336: 46013 | G336: 46015 | H336: PTO | I336: Approved | J336: =NETWORKDAYS(Christus_Emp_Table[[#This Row],[From Date:]],Christus_Emp_Table[[#This Row],[To Date:]]) -> 3 | L336: =_xlfn.XLOOKUP(Christus_Emp_Table[[#This Row],[Analyst Name:]],[1]!Table1[Analyst Name],[1]!Table1[Lead]) -> #REF! | M336: =_xlfn.XLOOKUP(Christus_Emp_Table[[#This Row],[Analyst Name:]],[1]!Table1[Analyst Name],[1]!Table1[Active/Inactive]) -> #REF!
A337: Sujitha Satti | B337: =_xlfn.XLOOKUP(Christus_Emp_Table[[#This Row],[Analyst Name:]],[1]!Table1[Analyst Name],[1]!Table1[Deloitte Email ID]) -> #REF! | C337: =_xlfn.XLOOKUP(Christus_Emp_Table[[#This Row],[Analyst Name:]],[1]!Table1[Analyst Name],[1]!Table1[Module]) -> #REF! | D337: =_xlfn.XLOOKUP(Christus_Emp_Table[[#This Row],[Analyst Name:]],[1]!Table1[Analyst Name],[1]!Table1[Location]) -> #REF! | E337: PTO | F337: 46013 | G337: 46015 | H337: PTO | I337: Approved | J337: =NETWORKDAYS(Christus_Emp_Table[[#This Row],[From Date:]],Christus_Emp_Table[[#This Row],[To Date:]]) -> 3 | L337: =_xlfn.XLOOKUP(Christus_Emp_Table[[#This Row],[Analyst Name:]],[1]!Table1[Analyst Name],[1]!Table1[Lead]) -> #REF! | M337: =_xlfn.XLOOKUP(Christus_Emp_Table[[#This Row],[Analyst Name:]],[1]!Table1[Analyst Name],[1]!Table1[Active/Inactive]) -> #REF!
A338: Pragati Rawat | B338: =_xlfn.XLOOKUP(Christus_Emp_Table[[#This Row],[Analyst Name:]],[1]!Table1[Analyst Name],[1]!Table1[Deloitte Email ID]) -> #REF! | C338: =_xlfn.XLOOKUP(Christus_Emp_Table[[#This Row],[Analyst Name:]],[1]!Table1[Analyst Name],[1]!Table1[Module]) -> #REF! | D338: =_xlfn.XLOOKUP(Christus_Emp_Table[[#This Row],[Analyst Name:]],[1]!Table1[Analyst Name],[1]!Table1[Location]) -> #REF! | E338: PTO | F338: 46013 | G338: 46015 | H338: PTO | I338: Approved | J338: =NETWORKDAYS(Christus_Emp_Table[[#This Row],[From Date:]],Christus_Emp_Table[[#This Row],[To Date:]]) -> 3 | L338: =_xlfn.XLOOKUP(Christus_Emp_Table[[#This Row],[Analyst Name:]],[1]!Table1[Analyst Name],[1]!Table1[Lead]) -> #REF! | M338: =_xlfn.XLOOKUP(Christus_Emp_Table[[#This Row],[Analyst Name:]],[1]!Table1[Analyst Name],[1]!Table1[Active/Inactive]) -> #REF!
A339: Parth Zalavadia | B339: =_xlfn.XLOOKUP(Christus_Emp_Table[[#This Row],[Analyst Name:]],[1]!Table1[Analyst Name],[1]!Table1[Deloitte Email ID]) -> #REF! | C339: =_xlfn.XLOOKUP(Christus_Emp_Table[[#This Row],[Analyst Name:]],[1]!Table1[Analyst Name],[1]!Table1[Module]) -> #REF! | D339: =_xlfn.XLOOKUP(Christus_Emp_Table[[#This Row],[Analyst Name:]],[1]!Table1[Analyst Name],[1]!Table1[Location]) -> #REF! | E339: Emergency | F339: 45995 | G339: 45995 | H339: Sick Leave | I339: Approved | J339: =NETWORKDAYS(Christus_Emp_Table[[#This Row],[From Date:]],Christus_Emp_Table[[#This Row],[To Date:]]) -> 1 | L339: =_xlfn.XLOOKUP(Christus_Emp_Table[[#This Row],[Analyst Name:]],[1]!Table1[Analyst Name],[1]!Table1[Lead]) -> #REF! | M339: =_xlfn.XLOOKUP(Christus_Emp_Table[[#This Row],[Analyst Name:]],[1]!Table1[Analyst Name],[1]!Table1[Active/Inactive]) -> #REF!
A340: Robin babu | B340: =_xlfn.XLOOKUP(Christus_Emp_Table[[#This Row],[Analyst Name:]],[1]!Table1[Analyst Name],[1]!Table1[Deloitte Email ID]) -> #REF! | C340: =_xlfn.XLOOKUP(Christus_Emp_Table[[#This Row],[Analyst Name:]],[1]!Table1[Analyst Name],[1]!Table1[Module]) -> #REF! | D340: =_xlfn.XLOOKUP(Christus_Emp_Table[[#This Row],[Analyst Name:]],[1]!Table1[Analyst Name],[1]!Table1[Location]) -> #REF! | E340: Emergency | F340: 46010 | G340: 46010 | H340: Sick Leave | I340: Approved | J340: =NETWORKDAYS(Christus_Emp_Table[[#This Row],[From Date:]],Christus_Emp_Table[[#This Row],[To Date:]]) -> 1 | L340: =_xlfn.XLOOKUP(Christus_Emp_Table[[#This Row],[Analyst Name:]],[1]!Table1[Analyst Name],[1]!Table1[Lead]) -> #REF! | M340: =_xlfn.XLOOKUP(Christus_Emp_Table[[#This Row],[Analyst Name:]],[1]!Table1[Analyst Name],[1]!Table1[Active/Inactive]) -> #REF!
A341: Pavani B Raj | B341: =_xlfn.XLOOKUP(Christus_Emp_Table[[#This Row],[Analyst Name:]],[1]!Table1[Analyst Name],[1]!Table1[Deloitte Email ID]) -> #REF! | C341: =_xlfn.XLOOKUP(Christus_Emp_Table[[#This Row],[Analyst Name:]],[1]!Table1[Analyst Name],[1]!Table1[Module]) -> #REF! | D341: =_xlfn.XLOOKUP(Christus_Emp_Table[[#This Row],[Analyst Name:]],[1]!Table1[Analyst Name],[1]!Table1[Location]) -> #REF! | E341: Emergency | F341: 45994 | G341: 45994 | H341: Sick Leave | I341: Approved | J341: =NETWORKDAYS(Christus_Emp_Table[[#This Row],[From Date:]],Christus_Emp_Table[[#This Row],[To Date:]]) -> 1 | L341: =_xlfn.XLOOKUP(Christus_Emp_Table[[#This Row],[Analyst Name:]],[1]!Table1[Analyst Name],[1]!Table1[Lead]) -> #REF! | M341: =_xlfn.XLOOKUP(Christus_Emp_Table[[#This Row],[Analyst Name:]],[1]!Table1[Analyst Name],[1]!Table1[Active/Inactive]) -> #REF!
... A380: Tanu Gupta | B380: =_xlfn.XLOOKUP(Christus_Emp_Table[[#This Row],[Analyst Name:]],[1]!Table1[Analyst Name],[1]!Table1[Deloitte Email ID]) -> #REF! | C380: =_xlfn.XLOOKUP(Christus_Emp_Table[[#This Row],[Analyst Name:]],[1]!Table1[Analyst Name],[1]!Table1[Module]) -> #REF! | D380: =_xlfn.XLOOKUP(Christus_Emp_Table[[#This Row],[Analyst Name:]],[1]!Table1[Analyst Name],[1]!Table1[Location]) -> #REF! | E380: Emergency | F380: 46038 | G380: 46038 | H380: Sick Leave | I380: Approved | J380: =NETWORKDAYS(Christus_Emp_Table[[#This Row],[From Date:]],Christus_Emp_Table[[#This Row],[To Date:]]) -> 1 | L380: =_xlfn.XLOOKUP(Christus_Emp_Table[[#This Row],[Analyst Name:]],[1]!Table1[Analyst Name],[1]!Table1[Lead]) -> #REF! | M380: =_xlfn.XLOOKUP(Christus_Emp_Table[[#This Row],[Analyst Name:]],[1]!Table1[Analyst Name],[1]!Table1[Active/Inactive]) -> #REF!
A381: Tanuja, Sunkara | B381: =_xlfn.XLOOKUP(Christus_Emp_Table[[#This Row],[Analyst Name:]],[1]!Table1[Analyst Name],[1]!Table1[Deloitte Email ID]) -> #REF! | C381: =_xlfn.XLOOKUP(Christus_Emp_Table[[#This Row],[Analyst Name:]],[1]!Table1[Analyst Name],[1]!Table1[Module]) -> #REF! | D381: =_xlfn.XLOOKUP(Christus_Emp_Table[[#This Row],[Analyst Name:]],[1]!Table1[Analyst Name],[1]!Table1[Location]) -> #REF! | E381: PTO | F381: 46049 | G381: 46049 | H381: Going to my Home town | I381: Approved | J381: =NETWORKDAYS(Christus_Emp_Table[[#This Row],[From Date:]],Christus_Emp_Table[[#This Row],[To Date:]]) -> 1 | K381: Sent | L381: =_xlfn.XLOOKUP(Christus_Emp_Table[[#This Row],[Analyst Name:]],[1]!Table1[Analyst Name],[1]!Table1[Lead]) -> #REF! | M381: =_xlfn.XLOOKUP(Christus_Emp_Table[[#This Row],[Analyst Name:]],[1]!Table1[Analyst Name],[1]!Table1[Active/Inactive]) -> #REF!
A382: Divya Maheshwari | B382: =_xlfn.XLOOKUP(Christus_Emp_Table[[#This Row],[Analyst Name:]],[1]!Table1[Analyst Name],[1]!Table1[Deloitte Email ID]) -> #REF! | C382: =_xlfn.XLOOKUP(Christus_Emp_Table[[#This Row],[Analyst Name:]],[1]!Table1[Analyst Name],[1]!Table1[Module]) -> #REF! | D382: =_xlfn.XLOOKUP(Christus_Emp_Table[[#This Row],[Analyst Name:]],[1]!Table1[Analyst Name],[1]!Table1[Location]) -> #REF! | E382: Emergency | F382: 46042 | G382: 46042 | H382: Sick Leave | I382: Approved | J382: =NETWORKDAYS(Christus_Emp_Table[[#This Row],[From Date:]],Christus_Emp_Table[[#This Row],[To Date:]]) -> 1 | L382: =_xlfn.XLOOKUP(Christus_Emp_Table[[#This Row],[Analyst Name:]],[1]!Table1[Analyst Name],[1]!Table1[Lead]) -> #REF! | M382: =_xlfn.XLOOKUP(Christus_Emp_Table[[#This Row],[Analyst Name:]],[1]!Table1[Analyst Name],[1]!Table1[Active/Inactive]) -> #REF!
A383: Tanu Gupta | B383: =_xlfn.XLOOKUP(Christus_Emp_Table[[#This Row],[Analyst Name:]],[1]!Table1[Analyst Name],[1]!Table1[Deloitte Email ID]) -> #REF! | C383: =_xlfn.XLOOKUP(Christus_Emp_Table[[#This Row],[Analyst Name:]],[1]!Table1[Analyst Name],[1]!Table1[Module]) -> #REF! | D383: =_xlfn.XLOOKUP(Christus_Emp_Table[[#This Row],[Analyst Name:]],[1]!Table1[Analyst Name],[1]!Table1[Location]) -> #REF! | E383: PTO | F383: 46083 | G383: 46083 | H383: Going home for Holi festival | I383: Draft | J383: =NETWORKDAYS(Christus_Emp_Table[[#This Row],[From Date:]],Christus_Emp_Table[[#This Row],[To Date:]]) -> 1 | L383: =_xlfn.XLOOKUP(Christus_Emp_Table[[#This Row],[Analyst Name:]],[1]!Table1[Analyst Name],[1]!Table1[Lead]) -> #REF! | M383: =_xlfn.XLOOKUP(Christus_Emp_Table[[#This Row],[Analyst Name:]],[1]!Table1[Analyst Name],[1]!Table1[Active/Inactive]) -> #REF!
A384: Tanu Gupta | B384: =_xlfn.XLOOKUP(Christus_Emp_Table[[#This Row],[Analyst Name:]],[1]!Table1[Analyst Name],[1]!Table1[Deloitte Email ID]) -> #REF! | C384: =_xlfn.XLOOKUP(Christus_Emp_Table[[#This Row],[Analyst Name:]],[1]!Table1[Analyst Name],[1]!Table1[Module]) -> #REF! | D384: =_xlfn.XLOOKUP(Christus_Emp_Table[[#This Row],[Analyst Name:]],[1]!Table1[Analyst Name],[1]!Table1[Location]) -> #REF! | E384: PTO | F384: 46085 | G384: 46085 | H384: Going home for Holi festival | I384: Draft | J384: =NETWORKDAYS(Christus_Emp_Table[[#This Row],[From Date:]],Christus_Emp_Table[[#This Row],[To Date:]]) -> 1 | L384: =_xlfn.XLOOKUP(Christus_Emp_Table[[#This Row],[Analyst Name:]],[1]!Table1[Analyst Name],[1]!Table1[Lead]) -> #REF! | M384: =_xlfn.XLOOKUP(Christus_Emp_Table[[#This Row],[Analyst Name:]],[1]!Table1[Analyst Name],[1]!Table1[Active/Inactive]) -> #REF!
A385: Charan S | B385: =_xlfn.XLOOKUP(Christus_Emp_Table[[#This Row],[Analyst Name:]],[1]!Table1[Analyst Name],[1]!Table1[Deloitte Email ID]) -> #REF! | C385: =_xlfn.XLOOKUP(Christus_Emp_Table[[#This Row],[Analyst Name:]],[1]!Table1[Analyst Name],[1]!Table1[Module]) -> #REF! | D385: =_xlfn.XLOOKUP(Christus_Emp_Table[[#This Row],[Analyst Name:]],[1]!Table1[Analyst Name],[1]!Table1[Location]) -> #REF! | E385: Emergency | F385: 46049 | G385: 46050 | H385: Sick Leave | I385: Approved | J385: =NETWORKDAYS(Christus_Emp_Table[[#This Row],[From Date:]],Christus_Emp_Table[[#This Row],[To Date:]]) -> 2 | L385: =_xlfn.XLOOKUP(Christus_Emp_Table[[#This Row],[Analyst Name:]],[1]!Table1[Analyst Name],[1]!Table1[Lead]) -> #REF! | M385: =_xlfn.XLOOKUP(Christus_Emp_Table[[#This Row],[Analyst Name:]],[1]!Table1[Analyst Name],[1]!Table1[Active/Inactive]) -> #REF!
A386: Amisha Shaw | B386: =_xlfn.XLOOKUP(Christus_Emp_Table[[#This Row],[Analyst Name:]],[1]!Table1[Analyst Name],[1]!Table1[Deloitte Email ID]) -> #REF! | C386: =_xlfn.XLOOKUP(Christus_Emp_Table[[#This Row],[Analyst Name:]],[1]!Table1[Analyst Name],[1]!Table1[Module]) -> #REF! | D386: =_xlfn.XLOOKUP(Christus_Emp_Table[[#This Row],[Analyst Name:]],[1]!Table1[Analyst Name],[1]!Table1[Location]) -> #REF! | E386: Emergency | F386: 46050 | G386: 46050 | H386: Sick Leave | I386: Approved | J386: =NETWORKDAYS(Christus_Emp_Table[[#This Row],[From Date:]],Christus_Emp_Table[[#This Row],[To Date:]]) -> 1 | L386: =_xlfn.XLOOKUP(Christus_Emp_Table[[#This Row],[Analyst Name:]],[1]!Table1[Analyst Name],[1]!Table1[Lead]) -> #REF! | M386: =_xlfn.XLOOKUP(Christus_Emp_Table[[#This Row],[Analyst Name:]],[1]!Table1[Analyst Name],[1]!Table1[Active/Inactive]) -> #REF!
A387: Amisha Shaw | B387: =_xlfn.XLOOKUP(Christus_Emp_Table[[#This Row],[Analyst Name:]],[1]!Table1[Analyst Name],[1]!Table1[Deloitte Email ID]) -> #REF! | C387: =_xlfn.XLOOKUP(Christus_Emp_Table[[#This Row],[Analyst Name:]],[1]!Table1[Analyst Name],[1]!Table1[Module]) -> #REF! | D387: =_xlfn.XLOOKUP(Christus_Emp_Table[[#This Row],[Analyst Name:]],[1]!Table1[Analyst Name],[1]!Table1[Location]) -> #REF! | E387: Half Day | F387: 46049 | G387: 46049 | H387: Sick leave | I387: Approved | J387: =NETWORKDAYS(Christus_Emp_Table[[#This Row],[From Date:]],Christus_Emp_Table[[#This Row],[To Date:]]) -> 1 | L387: =_xlfn.XLOOKUP(Christus_Emp_Table[[#This Row],[Analyst Name:]],[1]!Table1[Analyst Name],[1]!Table1[Lead]) -> #REF! | M387: =_xlfn.XLOOKUP(Christus_Emp_Table[[#This Row],[Analyst Name:]],[1]!Table1[Analyst Name],[1]!Table1[Active/Inactive]) -> #REF!
A388: Robin babu | B388: =_xlfn.XLOOKUP(Christus_Emp_Table[[#This Row],[Analyst Name:]],[1]!Table1[Analyst Name],[1]!Table1[Deloitte Email ID]) -> #REF! | C388: =_xlfn.XLOOKUP(Christus_Emp_Table[[#This Row],[Analyst Name:]],[1]!Table1[Analyst Name],[1]!Table1[Module]) -> #REF! | D388: =_xlfn.XLOOKUP(Christus_Emp_Table[[#This Row],[Analyst Name:]],[1]!Table1[Analyst Name],[1]!Table1[Location]) -> #REF! | E388: Emergency | F388: 46049 | G388: 46050 | H388: Emergency PTO | I388: Approved | J388: =NETWORKDAYS(Christus_Emp_Table[[#This Row],[From Date:]],Christus_Emp_Table[[#This Row],[To Date:]]) -> 2 | L388: =_xlfn.XLOOKUP(Christus_Emp_Table[[#This Row],[Analyst Name:]],[1]!Table1[Analyst Name],[1]!Table1[Lead]) -> #REF! | M388: =_xlfn.XLOOKUP(Christus_Emp_Table[[#This Row],[Analyst Name:]],[1]!Table1[Analyst Name],[1]!Table1[Active/Inactive]) -> #REF!
A389: Bharti Kumari | B389: =_xlfn.XLOOKUP(Christus_Emp_Table[[#This Row],[Analyst Name:]],[1]!Table1[Analyst Name],[1]!Table1[Deloitte Email ID]) -> #REF! | C389: =_xlfn.XLOOKUP(Christus_Emp_Table[[#This Row],[Analyst Name:]],[1]!Table1[Analyst Name],[1]!Table1[Module]) -> #REF! | D389: =_xlfn.XLOOKUP(Christus_Emp_Table[[#This Row],[Analyst Name:]],[1]!Table1[Analyst Name],[1]!Table1[Location]) -> #REF! | E389: PTO | F389: 46049 | G389: 46073 | H389: Marriage | I389: Approved | J389: =NETWORKDAYS(Christus_Emp_Table[[#This Row],[From Date:]],Christus_Emp_Table[[#This Row],[To Date:]]) -> 19 | K389: Sent | L389: =_xlfn.XLOOKUP(Christus_Emp_Table[[#This Row],[Analyst Name:]],[1]!Table1[Analyst Name],[1]!Table1[Lead]) -> #REF! | M389: =_xlfn.XLOOKUP(Christus_Emp_Table[[#This Row],[Analyst Name:]],[1]!Table1[Analyst Name],[1]!Table1[Active/Inactive]) -> #REF!
A390: Friendsis Rai | B390: =_xlfn.XLOOKUP(Christus_Emp_Table[[#This Row],[Analyst Name:]],[1]!Table1[Analyst Name],[1]!Table1[Deloitte Email ID]) -> #REF! | C390: =_xlfn.XLOOKUP(Christus_Emp_Table[[#This Row],[Analyst Name:]],[1]!Table1[Analyst Name],[1]!Table1[Module]) -> #REF! | D390: =_xlfn.XLOOKUP(Christus_Emp_Table[[#This Row],[Analyst Name:]],[1]!Table1[Analyst Name],[1]!Table1[Location]) -> #REF! | E390: PTO | F390: 46069 | G390: 46071 | H390: I'll be visiting my sister | I390: Draft | J390: =NETWORKDAYS(Christus_Emp_Table[[#This Row],[From Date:]],Christus_Emp_Table[[#This Row],[To Date:]]) -> 3 | L390: =_xlfn.XLOOKUP(Christus_Emp_Table[[#This Row],[Analyst Name:]],[1]!Table1[Analyst Name],[1]!Table1[Lead]) -> #REF! | M390: =_xlfn.XLOOKUP(Christus_Emp_Table[[#This Row],[Analyst Name:]],[1]!Table1[Analyst Name],[1]!Table1[Active/Inactive]) -> #REF!
A391: Pragati Rawat | B391: =_xlfn.XLOOKUP(Christus_Emp_Table[[#This Row],[Analyst Name:]],[1]!Table1[Analyst Name],[1]!Table1[Deloitte Email ID]) -> #REF! | C391: =_xlfn.XLOOKUP(Christus_Emp_Table[[#This Row],[Analyst Name:]],[1]!Table1[Analyst Name],[1]!Table1[Module]) -> #REF! | D391: =_xlfn.XLOOKUP(Christus_Emp_Table[[#This Row],[Analyst Name:]],[1]!Table1[Analyst Name],[1]!Table1[Location]) -> #REF! | E391: PTO | F391: 46073 | G391: 46073 | H391: Personal Reason | I391: Draft | J391: =NETWORKDAYS(Christus_Emp_Table[[#This Row],[From Date:]],Christus_Emp_Table[[#This Row],[To Date:]]) -> 1 | L391: =_xlfn.XLOOKUP(Christus_Emp_Table[[#This Row],[Analyst Name:]],[1]!Table1[Analyst Name],[1]!Table1[Lead]) -> #REF! | M391: =_xlfn.XLOOKUP(Christus_Emp_Table[[#This Row],[Analyst Name:]],[1]!Table1[Analyst Name],[1]!Table1[Active/Inactive]) -> #REF!
A392: Abburi Durga Grishmitha | B392: =_xlfn.XLOOKUP(Christus_Emp_Table[[#This Row],[Analyst Name:]],[1]!Table1[Analyst Name],[1]!Table1[Deloitte Email ID]) -> #REF! | C392: =_xlfn.XLOOKUP(Christus_Emp_Table[[#This Row],[Analyst Name:]],[1]!Table1[Analyst Name],[1]!Table1[Module]) -> #REF! | D392: =_xlfn.XLOOKUP(Christus_Emp_Table[[#This Row],[Analyst Name:]],[1]!Table1[Analyst Name],[1]!Table1[Location]) -> #REF! | E392: PTO | F392: 46055 | G392: 46055 | H392: Attendance at Deloitte University | I392: Approved | J392: =NETWORKDAYS(Christus_Emp_Table[[#This Row],[From Date:]],Christus_Emp_Table[[#This Row],[To Date:]]) -> 1 | L392: =_xlfn.XLOOKUP(Christus_Emp_Table[[#This Row],[Analyst Name:]],[1]!Table1[Analyst Name],[1]!Table1[Lead]) -> #REF! | M392: =_xlfn.XLOOKUP(Christus_Emp_Table[[#This Row],[Analyst Name:]],[1]!Table1[Analyst Name],[1]!Table1[Active/Inactive]) -> #REF!
...

Sheet EmployeeData
A1: Analyst Name: | B1: Deloitte Email ID: | C1: Module: | D1: Location: | E1: PTO Type: | F1: From Date: | G1: To Date: | H1: Reason of PTO: | I1: Status: | J1: PTO Count | K1: Email Status | L1: Approver
A2: Ujjwal waikar | B2: dwaikar@deloitte.com | C2: SER | D2: BLR | E2: PTO | F2: 46069 | G2: 46073 | H2: PTO | I2: Approved | J2: 5 | L2: Ankita Roy
A3: Rachana, Golla | B3: racharachana@deloitte.com | C3: Reporting | D3: HYD | E3: PTO | F3: 46055 | G3: 46058 | H3: Vacation | I3: Approved | J3: 4 | L3: Nitish Kumar
A4: Divya Maheshwari | B4: divmaheshwari@deloitte.com | C4: MyChart | D4: GUR | E4: PTO | F4: 46057 | G4: 46059 | H4: To attend Wedding | I4: Approved | J4: 3 | K4: Sent | L4: Nitish Kumar
A5: Parth Zalavadia | B5: pjagdishzalavadia@deloitte.com | C5: Bridges | D5: BLR | E5: PTO | F5: 46064 | G5: 46066 | H5: Personal reason | I5: Approved | J5: 3 | L5: Tanima Debmallik/Nitish Kumar
A6: Tanu Gupta | B6: tgupta10@deloitte.com | C6: Automation | D6: HYD | E6: PTO | F6: 46055 | G6: 46055 | H6: Test | I6: Approved | J6: 1 | L6: Parth Zalavadia
A7: Tanu Gupta | B7: tgupta10@deloitte.com | C7: Automation | D7: HYD | E7: PTO | F7: 46024 | G7: 46024 | H7: PTO | I7: Approved | J7: 1 | L7: Parth Zalavadia
A8: Pavani B Raj | B8: pbraj@deloitte.com | C8: Automation | D8: BLR | E8: PTO | F8: 46024 | G8: 46024 | H8: PTO | I8: Approved | J8: 1 | L8: Nitish Kumar
A9: Sujitha Satti | B9: susujitha@deloitte.com | C9: QA | D9: HYD | E9: PTO | F9: 46024 | G9: 46024 | H9: PTO | I9: Approved | J9: 1 | L9: Ankita Roy
A10: Anusree Saha | B10: anussaha@deloitte.com | C10: Automation | D10: HYD | E10: PTO | F10: 46024 | G10: 46024 | H10: PTO | I10: Approved | J10: 1 | L10: Nitish Kumar
A11: Sruthi G | B11: srug@deloitte.com | C11: Reporting | D11: BLR | E11: PTO | F11: 46024 | G11: 46024 | H11: PTO | I11: Approved | J11: 1 | L11: Jagannath Belel
A12: Sanchi Yadav | B12: sancyadav@deloitte.com | C12: Reporting | D12: HYD | E12: PTO | F12: 46024 | G12: 46024 | H12: PTO | I12: Approved | J12: 1 | L12: Nitish Kumar
A13: Gollapudi, Gireesh | B13: gigollapudi@deloitte.com | C13: Reporting | D13: HYD | E13: PTO | F13: 46024 | G13: 46024 | H13: PTO | I13: Approved | J13: 1 | L13: Jagannath Belel
A14: Abburi Durga Grishmitha | B14: agrishmitha@deloitte.com | C14: MyChart | D14: HYD | E14: PTO | F14: 46024 | G14: 46024 | H14: PTO | I14: Approved | J14: 1 | L14: Nitish Kumar
A15: Meghana Baddam | B15: bmeghana@deloitte.com | C15: Bridges | D15: BLR | E15: PTO | F15: 46024 | G15: 46024 | H15: PTO | I15: Approved | J15: 1 | L15: Parth Zalavadia
A16: Harshit Malpani | B16: hamalpani@deloitte.com | C16: MyChart | D16: HYD | E16: PTO | F16: 46038 | G16: 46041 | H16: PTO | I16: Approved | J16: 2 | L16: Nitish Kumar
A17: Lavleen Kaur | B17: lakaur@deloitte.com | C17: SER | D17: GUR | E17: PTO | F17: 46030 | G17: 46034 | H17: PTO | I17: Approved | J17: 3 | L17: Ankita Roy
A18: Ankita Roy | B18: ankitaroy2@deloitte.com | C18: EC/DC | D18: BLR | E18: PTO | F18: 46024 | G18: 46031 | H18: PTO | I18: Approved | J18: 6 | L18: 0
A19: Akshaya Kumar | B19: akshayakumar@deloitte.com | C19: Automation | D19: BLR | E19: PTO | F19: 46030 | G19: 46031 | H19: PTO | I19: Approved | J19: 2 | L19: Parth Zalavadia
A20: Ujjwal waikar | B20: dwaikar@deloitte.com | C20: SER | D20: BLR | E20: Emergency | F20: 46029 | G20: 46029 | H20: Sick Leave | I20: Approved | J20: 1 | L20: Ankita Roy
A21: Gollapudi, Gireesh | B21: gigollapudi@deloitte.com | C21: Reporting | D21: HYD | E21: PTO | F21: 46038 | G21: 46038 | H21: PTO | I21: Approved | J21: 1 | L21: Jagannath Belel
A22: Pragati Rawat | B22: pragrawat@deloitte.com | C22: EC/DC | D22: GUR | E22: PTO | F22: 46038 | G22: 46038 | H22: PTO | I22: Approved | J22: 1 | L22: Ankita Roy
A23: Tanu Gupta | B23: tgupta10@deloitte.com | C23: Automation | D23: HYD | E23: Emergency | F23: 46038 | G23: 46038 | H23: Sick Leave | I23: Approved | J23: 1 | L23: Parth Zalavadia
A24: Tanuja, Sunkara | B24: stanuja@deloitte.com | C24: QA | D24: HYD | E24: PTO | F24: 46049 | G24: 46049 | H24: Going to my Home town | I24: Approved | J24: 1 | K24: Sent | L24: Ankita Roy
A25: Divya Maheshwari | B25: divmaheshwari@deloitte.com | C25: MyChart | D25: GUR | E25: Emergency | F25: 46042 | G25: 46042 | H25: Sick Leave | I25: Approved | J25: 1 | L25: Nitish Kumar
A26: Charan S | B26: scharan1@deloitte.com | C26: Bridges | D26: HYD | E26: Emergency | F26: 46049 | G26: 46050 | H26: Sick Leave | I26: Approved | J26: 2 | L26: Nitish Kumar
A27: Amisha Shaw | B27: amisshaw@deloitte.com | C27: Automation | D27: MUM | E27: Emergency | F27: 46050 | G27: 46050 | H27: Sick Leave | I27: Approved | J27: 1 | L27: Nitish Kumar
A28: Charan S | B28: scharan1@deloitte.com | C28: Bridges | D28: HYD | E28: Emergency | F28: 46049 | G28: 46050 | H28: Sick Leave | I28: Approved | J28: 2 | L28: Nitish Kumar
A29: Robin babu | B29: rmbabu@deloitte.com | C29: ECLink | D29: HYD | E29: Emergency | F29: 46049 | G29: 46050 | H29: Emergency PTO | I29: Approved | J29: 2 | L29: Nitish Kumar
A30: Bharti Kumari | B30: bharkumari@deloitte.com | C30: Reporting | D30: BLR | E30: PTO | F30: 46049 | G30: 46073 | H30: Marriage | I30: Approved | J30: 19 | K30: Sent | L30: Nitish Kumar
A31: Kiran Kumar S | F31: 46034

Sheet Jan
A1: CHRISTUS Health Monthly Leave Calendar - 2026
A2: January
A4: Team Members | B4: =IF(B5="","",INDEX({"Sun";"Mon";"Tue";"Wed";"Thu";"Fri";"Sat"},WEEKDAY(B5,1))) -> Thu | C4: =IF(C5="","",INDEX({"Sun";"Mon";"Tue";"Wed";"Thu";"Fri";"Sat"},WEEKDAY(C5,1))) -> Fri | D4: =IF(D5="","",INDEX({"Sun";"Mon";"Tue";"Wed";"Thu";"Fri";"Sat"},WEEKDAY(D5,1))) -> Sat | E4: =IF(E5="","",INDEX({"Sun";"Mon";"Tue";"Wed";"Thu";"Fri";"Sat"},WEEKDAY(E5,1))) -> Sun | F4: =IF(F5="","",INDEX({"Sun";"Mon";"Tue";"Wed";"Thu";"Fri";"Sat"},WEEKDAY(F5,1))) -> Mon | G4: =IF(G5="","",INDEX({"Sun";"Mon";"Tue";"Wed";"Thu";"Fri";"Sat"},WEEKDAY(G5,1))) -> Tue | H4: =IF(H5="","",INDEX({"Sun";"Mon";"Tue";"Wed";"Thu";"Fri";"Sat"},WEEKDAY(H5,1))) -> Wed | I4: =IF(I5="","",INDEX({"Sun";"Mon";"Tue";"Wed";"Thu";"Fri";"Sat"},WEEKDAY(I5,1))) -> Thu | ... AF4: =IF(AF5="","",INDEX({"Sun";"Mon";"Tue";"Wed";"Thu";"Fri";"Sat"},WEEKDAY(AF5,1))) -> Sat | AG4: Total Absence Days | AH4: Total Vacation Leave Days | AI4: Total Sick/Emergency Leave Days | AJ4: Maternity or Paternity | AK4: Leave without Pay | AM4: Absence type | AN4: Code
B5: =DATE(Year!$B$2,1,1) -> 46023 | C5: =B5+1 -> 46024 | D5: =C5+1 -> 46025 | E5: =D5+1 -> 46026 | F5: =E5+1 -> 46027 | G5: =F5+1 -> 46028 | H5: =G5+1 -> 46029 | I5: =H5+1 -> 46030 | J5: =I5+1 -> 46031 | ... AF5: =AE5+1 -> 46053
A6: Nitish Kumar | B6: FH | C6: =IF(COUNTIFS(EmployeeData!$A:$A,$A6,EmployeeData!$F:$F,C$5)>0,"PT","") | D6: =IF(COUNTIFS(EmployeeData!$A:$A,$A6,EmployeeData!$F:$F,D$5)>0,"PT","") | E6: =IF(COUNTIFS(EmployeeData!$A:$A,$A6,EmployeeData!$F:$F,E$5)>0,"PT","") | F6: =IF(COUNTIFS(EmployeeData!$A:$A,$A6,EmployeeData!$F:$F,F$5)>0,"PT","") | G6: =IF(COUNTIFS(EmployeeData!$A:$A,$A6,EmployeeData!$F:$F,G$5)>0,"PT","") | H6: =IF(COUNTIFS(EmployeeData!$A:$A,$A6,EmployeeData!$F:$F,H$5)>0,"PT","") | I6: =IF(COUNTIFS(EmployeeData!$A:$A,$A6,EmployeeData!$F:$F,I$5)>0,"PT","") | J6: =IF(COUNTIFS(EmployeeData!$A:$A,$A6,EmployeeData!$F:$F,J$5)>0,"PT","") | ... Z6: =IF(COUNTIFS(EmployeeData!$A:$A,$A6,EmployeeData!$F:$F,Z$5)>0,"PT","") | AA6: FH | AB6: =IF(COUNTIFS(EmployeeData!$A:$A,$A6,EmployeeData!$F:$F,AB$5)>0,"PT","") | AC6: =IF(COUNTIFS(EmployeeData!$A:$A,$A6,EmployeeData!$F:$F,AC$5)>0,"PT","") | AD6: =IF(COUNTIFS(EmployeeData!$A:$A,$A6,EmployeeData!$F:$F,AD$5)>0,"PT","") | AE6: =IF(COUNTIFS(EmployeeData!$A:$A,$A6,EmployeeData!$F:$F,AE$5)>0,"PT","") | AF6: =IF(COUNTIFS(EmployeeData!$A:$A,$A6,EmployeeData!$F:$F,AF$5)>0,"PT","") | AG6: =(COUNTIF(B6:AF6,"PT")*1)+(COUNTIF(B6:AF6,"H1")*0.5)+(COUNTIF(B6:AF6,"T")*0)+(COUNTIF(B6:AF6,"R")*0)+(COUNTIF(B6:AF6,"S")*1)+(COUNTIF(B6:AF6,"C")*1)+(COUNTIF(B6:AF6,"FH")*0)+(COUNTIF(B6:AF6,"MT")*1) -> 0 | AH6: =COUNTIF(B6:AF6,"PT")+COUNTIF(B6:AF6,"H1")+COUNTIF(B6:AF6,"U") -> 0 | AI6: =COUNTIF(B6:AF6,"S")+COUNTIF(B6:AF6,"S1")/2+COUNTIF(B6:AF6,"S2")/2 -> 0 | AJ6: =COUNTIF(B6:AF6,"MT") -> 0 | AK6: =COUNTIF(B6:AF6,"U") -> 0 | AM6: PTO | AN6: PT
A7: Bharti Kumari | B7: FH | C7: =IF(COUNTIFS(EmployeeData!$A:$A,$A7,EmployeeData!$F:$F,C$5)>0,"PT","") | D7: =IF(COUNTIFS(EmployeeData!$A:$A,$A7,EmployeeData!$F:$F,D$5)>0,"PT","") | E7: =IF(COUNTIFS(EmployeeData!$A:$A,$A7,EmployeeData!$F:$F,E$5)>0,"PT","") | F7: =IF(COUNTIFS(EmployeeData!$A:$A,$A7,EmployeeData!$F:$F,F$5)>0,"PT","") | G7: =IF(COUNTIFS(EmployeeData!$A:$A,$A7,EmployeeData!$F:$F,G$5)>0,"PT","") | H7: =IF(COUNTIFS(EmployeeData!$A:$A,$A7,EmployeeData!$F:$F,H$5)>0,"PT","") | I7: =IF(COUNTIFS(EmployeeData!$A:$A,$A7,EmployeeData!$F:$F,I$5)>0,"PT","") | J7: =IF(COUNTIFS(EmployeeData!$A:$A,$A7,EmployeeData!$F:$F,J$5)>0,"PT","") | ... Z7: =IF(COUNTIFS(EmployeeData!$A:$A,$A7,EmployeeData!$F:$F,Z$5)>0,"PT","") | AA7: FH | AB7: =IF(COUNTIFS(EmployeeData!$A:$A,$A7,EmployeeData!$F:$F,AB$5)>0,"PT","") -> PT | AC7: =IF(COUNTIFS(EmployeeData!$A:$A,$A7,EmployeeData!$F:$F,AC$5)>0,"PT","") | AD7: =IF(COUNTIFS(EmployeeData!$A:$A,$A7,EmployeeData!$F:$F,AD$5)>0,"PT","") | AE7: =IF(COUNTIFS(EmployeeData!$A:$A,$A7,EmployeeData!$F:$F,AE$5)>0,"PT","") | AF7: =IF(COUNTIFS(EmployeeData!$A:$A,$A7,EmployeeData!$F:$F,AF$5)>0,"PT","") | AG7: =(COUNTIF(B7:AF7,"PT")*1)+(COUNTIF(B7:AF7,"H1")*0.5)+(COUNTIF(B7:AF7,"T")*0)+(COUNTIF(B7:AF7,"R")*0)+(COUNTIF(B7:AF7,"S")*1)+(COUNTIF(A7:B7,"C")*1)+(COUNTIF(B7:AF7,"FH")*0)+(COUNTIF(B7:AF7,"MT")*1) -> 1 | AH7: =COUNTIF(B7:AF7,"V")+COUNTIF(B7:AF7,"V1")/2+COUNTIF(B7:AF7,"V2")/2 -> 0 | AI7: =COUNTIF(B7:AF7,"S")+COUNTIF(B7:AF7,"S1")/2+COUNTIF(B7:AF7,"S2")/2 -> 0 | AJ7: =COUNTIF(B7:AF7,"M") -> 0 | AK7: =COUNTIF(B7:AF7,"U") -> 0 | AM7: Sick leave/ Emergency leave | AN7: S
A8: Sruthi G | B8: FH | C8: =IF(COUNTIFS(EmployeeData!$A:$A,$A8,EmployeeData!$F:$F,C$5)>0,"PT","") -> PT | D8: =IF(COUNTIFS(EmployeeData!$A:$A,$A8,EmployeeData!$F:$F,D$5)>0,"PT","") | E8: =IF(COUNTIFS(EmployeeData!$A:$A,$A8,EmployeeData!$F:$F,E$5)>0,"PT","") | F8: =IF(COUNTIFS(EmployeeData!$A:$A,$A8,EmployeeData!$F:$F,F$5)>0,"PT","") | G8: =IF(COUNTIFS(EmployeeData!$A:$A,$A8,EmployeeData!$F:$F,G$5)>0,"PT","") | H8: =IF(COUNTIFS(EmployeeData!$A:$A,$A8,EmployeeData!$F:$F,H$5)>0,"PT","") | I8: =IF(COUNTIFS(EmployeeData!$A:$A,$A8,EmployeeData!$F:$F,I$5)>0,"PT","") | J8: =IF(COUNTIFS(EmployeeData!$A:$A,$A8,EmployeeData!$F:$F,J$5)>0,"PT","") | ... Z8: =IF(COUNTIFS(EmployeeData!$A:$A,$A8,EmployeeData!$F:$F,Z$5)>0,"PT","") | AA8: FH | AB8: =IF(COUNTIFS(EmployeeData!$A:$A,$A8,EmployeeData!$F:$F,AB$5)>0,"PT","") | AC8: =IF(COUNTIFS(EmployeeData!$A:$A,$A8,EmployeeData!$F:$F,AC$5)>0,"PT","") | AD8: =IF(COUNTIFS(EmployeeData!$A:$A,$A8,EmployeeData!$F:$F,AD$5)>0,"PT","") | AE8: =IF(COUNTIFS(EmployeeData!$A:$A,$A8,EmployeeData!$F:$F,AE$5)>0,"PT","") | AF8: =IF(COUNTIFS(EmployeeData!$A:$A,$A8,EmployeeData!$F:$F,AF$5)>0,"PT","") | AG8: =(COUNTIF(B8:AF8,"PT")*1)+(COUNTIF(B8:AF8,"H1")*0.5)+(COUNTIF(B8:AF8,"T")*0)+(COUNTIF(B8:AF8,"R")*0)+(COUNTIF(B8:AF8,"S")*1)+(COUNTIF(B8:AF8,"C")*1)+(COUNTIF(B8:AF8,"FH")*0)+(COUNTIF(B8:AF8,"MT")*1) -> 1 | AH8: =COUNTIF(B8:AF8,"V")+COUNTIF(B8:AF8,"V1")/2+COUNTIF(B8:AF8,"V2")/2 -> 0 | AI8: =COUNTIF(B8:AF8,"S")+COUNTIF(B8:AF8,"S1")/2+COUNTIF(B8:AF8,"S2")/2 -> 0 | AJ8: =COUNTIF(B8:AF8,"M") -> 0 | AK8: =COUNTIF(B8:AF8,"U") -> 0 | AM8: Half Day | AN8: H1
A9: Balagopalan, Akhila | B9: FH | C9: =IF(COUNTIFS(EmployeeData!$A:$A,$A9,EmployeeData!$F:$F,C$5)>0,"PT","") | D9: =IF(COUNTIFS(EmployeeData!$A:$A,$A9,EmployeeData!$F:$F,D$5)>0,"PT","") | E9: =IF(COUNTIFS(EmployeeData!$A:$A,$A9,EmployeeData!$F:$F,E$5)>0,"PT","") | F9: =IF(COUNTIFS(EmployeeData!$A:$A,$A9,EmployeeData!$F:$F,F$5)>0,"PT","") | G9: =IF(COUNTIFS(EmployeeData!$A:$A,$A9,EmployeeData!$F:$F,G$5)>0,"PT","") | H9: =IF(COUNTIFS(EmployeeData!$A:$A,$A9,EmployeeData!$F:$F,H$5)>0,"PT","") | I9: =IF(COUNTIFS(EmployeeData!$A:$A,$A9,EmployeeData!$F:$F,I$5)>0,"PT","") | J9: =IF(COUNTIFS(EmployeeData!$A:$A,$A9,EmployeeData!$F:$F,J$5)>0,"PT","") | ... Z9: =IF(COUNTIFS(EmployeeData!$A:$A,$A9,EmployeeData!$F:$F,Z$5)>0,"PT","") | AA9: FH | AB9: =IF(COUNTIFS(EmployeeData!$A:$A,$A9,EmployeeData!$F:$F,AB$5)>0,"PT","") | AC9: =IF(COUNTIFS(EmployeeData!$A:$A,$A9,EmployeeData!$F:$F,AC$5)>0,"PT","") | AD9: =IF(COUNTIFS(EmployeeData!$A:$A,$A9,EmployeeData!$F:$F,AD$5)>0,"PT","") | AE9: =IF(COUNTIFS(EmployeeData!$A:$A,$A9,EmployeeData!$F:$F,AE$5)>0,"PT","") | AF9: =IF(COUNTIFS(EmployeeData!$A:$A,$A9,EmployeeData!$F:$F,AF$5)>0,"PT","") | AG9: =(COUNTIF(B9:AF9,"PT")*1)+(COUNTIF(B9:AF9,"H1")*0.5)+(COUNTIF(B9:AF9,"T")*0)+(COUNTIF(B9:AF9,"R")*0)+(COUNTIF(B9:AF9,"S")*1)+(COUNTIF(B9:AF9,"C")*1)+(COUNTIF(B9:AF9,"FH")*0)+(COUNTIF(B9:AF9,"MT")*1) -> 0 | AH9: =COUNTIF(B9:AF9,"V")+COUNTIF(B9:AF9,"V1")/2+COUNTIF(B9:AF9,"V2")/2 -> 0 | AI9: =COUNTIF(B9:AF9,"S")+COUNTIF(B9:AF9,"S1")/2+COUNTIF(B9:AF9,"S2")/2 -> 0 | AJ9: =COUNTIF(B9:AF9,"M") -> 0 | AK9: =COUNTIF(B9:AF9,"U") -> 0 | AM9: Maternity/Paternity | AN9: MT
A10: Jagannath Belel | B10: FH | C10: =IF(COUNTIFS(EmployeeData!$A:$A,$A10,EmployeeData!$F:$F,C$5)>0,"PT","") | D10: =IF(COUNTIFS(EmployeeData!$A:$A,$A10,EmployeeData!$F:$F,D$5)>0,"PT","") | E10: =IF(COUNTIFS(EmployeeData!$A:$A,$A10,EmployeeData!$F:$F,E$5)>0,"PT","") | F10: =IF(COUNTIFS(EmployeeData!$A:$A,$A10,EmployeeData!$F:$F,F$5)>0,"PT","") | G10: =IF(COUNTIFS(EmployeeData!$A:$A,$A10,EmployeeData!$F:$F,G$5)>0,"PT","") | H10: =IF(COUNTIFS(EmployeeData!$A:$A,$A10,EmployeeData!$F:$F,H$5)>0,"PT","") | I10: =IF(COUNTIFS(EmployeeData!$A:$A,$A10,EmployeeData!$F:$F,I$5)>0,"PT","") | J10: =IF(COUNTIFS(EmployeeData!$A:$A,$A10,EmployeeData!$F:$F,J$5)>0,"PT","") | ... Z10: =IF(COUNTIFS(EmployeeData!$A:$A,$A10,EmployeeData!$F:$F,Z$5)>0,"PT","") | AA10: FH | AB10: =IF(COUNTIFS(EmployeeData!$A:$A,$A10,EmployeeData!$F:$F,AB$5)>0,"PT","") | AC10: =IF(COUNTIFS(EmployeeData!$A:$A,$A10,EmployeeData!$F:$F,AC$5)>0,"PT","") | AD10: =IF(COUNTIFS(EmployeeData!$A:$A,$A10,EmployeeData!$F:$F,AD$5)>0,"PT","") | AE10: =IF(COUNTIFS(EmployeeData!$A:$A,$A10,EmployeeData!$F:$F,AE$5)>0,"PT","") | AF10: =IF(COUNTIFS(EmployeeData!$A:$A,$A10,EmployeeData!$F:$F,AF$5)>0,"PT","") | AG10: =(COUNTIF(B10:AF10,"PT")*1)+(COUNTIF(B10:AF10,"H1")*0.5)+(COUNTIF(B10:AF10,"T")*0)+(COUNTIF(B10:AF10,"R")*0)+(COUNTIF(B10:AF10,"S")*1)+(COUNTIF(B10:AF10,"C")*1)+(COUNTIF(B10:AF10,"FH")*0)+(COUNTIF(B10:AF10,"MT")*1) -> 0 | AH10: =COUNTIF(B10:AF10,"V")+COUNTIF(B10:AF10,"V1")/2+COUNTIF(B10:AF10,"V2")/2 -> 0 | AI10: =COUNTIF(B10:AF10,"S")+COUNTIF(B10:AF10,"S1")/2+COUNTIF(B10:AF10,"S2")/2 -> 0 | AJ10: =COUNTIF(B10:AF10,"M") -> 0 | AK10: =COUNTIF(B10:AF10,"U") -> 0 | AM10: Firm Holiday | AN10: FH
A11: Sanchi Yadav | B11: FH | C11: =IF(COUNTIFS(EmployeeData!$A:$A,$A11,EmployeeData!$F:$F,C$5)>0,"PT","") -> PT | D11: =IF(COUNTIFS(EmployeeData!$A:$A,$A11,EmployeeData!$F:$F,D$5)>0,"PT","") | E11: =IF(COUNTIFS(EmployeeData!$A:$A,$A11,EmployeeData!$F:$F,E$5)>0,"PT","") | F11: =IF(COUNTIFS(EmployeeData!$A:$A,$A11,EmployeeData!$F:$F,F$5)>0,"PT","") | G11: =IF(COUNTIFS(EmployeeData!$A:$A,$A11,EmployeeData!$F:$F,G$5)>0,"PT","") | H11: =IF(COUNTIFS(EmployeeData!$A:$A,$A11,EmployeeData!$F:$F,H$5)>0,"PT","") | I11: =IF(COUNTIFS(EmployeeData!$A:$A,$A11,EmployeeData!$F:$F,I$5)>0,"PT","") | J11: =IF(COUNTIFS(EmployeeData!$A:$A,$A11,EmployeeData!$F:$F,J$5)>0,"PT","") | ... Z11: =IF(COUNTIFS(EmployeeData!$A:$A,$A11,EmployeeData!$F:$F,Z$5)>0,"PT","") | AA11: FH | AB11: =IF(COUNTIFS(EmployeeData!$A:$A,$A11,EmployeeData!$F:$F,AB$5)>0,"PT","") | AC11: =IF(COUNTIFS(EmployeeData!$A:$A,$A11,EmployeeData!$F:$F,AC$5)>0,"PT","") | AD11: =IF(COUNTIFS(EmployeeData!$A:$A,$A11,EmployeeData!$F:$F,AD$5)>0,"PT","") | AE11: =IF(COUNTIFS(EmployeeData!$A:$A,$A11,EmployeeData!$F:$F,AE$5)>0,"PT","") | AF11: =IF(COUNTIFS(EmployeeData!$A:$A,$A11,EmployeeData!$F:$F,AF$5)>0,"PT","") | AG11: =(COUNTIF(B11:AF11,"PT")*1)+(COUNTIF(B11:AF11,"H1")*0.5)+(COUNTIF(B11:AF11,"T")*0)+(COUNTIF(B11:AF11,"R")*0)+(COUNTIF(B11:AF11,"S")*1)+(COUNTIF(B11:AF11,"C")*1)+(COUNTIF(B11:AF11,"FH")*0)+(COUNTIF(B11:AF11,"MT")*1) -> 1 | AH11: =COUNTIF(B11:AF11,"V")+COUNTIF(B11:AF11,"V1")/2+COUNTIF(B11:AF11,"V2")/2 -> 0 | AI11: =COUNTIF(B11:AF11,"S")+COUNTIF(B11:AF11,"S1")/2+COUNTIF(B11:AF11,"S2")/2 -> 0 | AJ11: =COUNTIF(B11:AF11,"M") -> 0 | AK11: =COUNTIF(B11:AF11,"U") -> 0 | AM11: Leave without Pay | AN11: U
A12: Gollapudi, Gireesh | B12: FH | C12: =IF(COUNTIFS(EmployeeData!$A:$A,$A12,EmployeeData!$F:$F,C$5)>0,"PT","") -> PT | D12: =IF(COUNTIFS(EmployeeData!$A:$A,$A12,EmployeeData!$F:$F,D$5)>0,"PT","") | E12: =IF(COUNTIFS(EmployeeData!$A:$A,$A12,EmployeeData!$F:$F,E$5)>0,"PT","") | F12: =IF(COUNTIFS(EmployeeData!$A:$A,$A12,EmployeeData!$F:$F,F$5)>0,"PT","") | G12: =IF(COUNTIFS(EmployeeData!$A:$A,$A12,EmployeeData!$F:$F,G$5)>0,"PT","") | H12: =IF(COUNTIFS(EmployeeData!$A:$A,$A12,EmployeeData!$F:$F,H$5)>0,"PT","") | I12: =IF(COUNTIFS(EmployeeData!$A:$A,$A12,EmployeeData!$F:$F,I$5)>0,"PT","") | J12: =IF(COUNTIFS(EmployeeData!$A:$A,$A12,EmployeeData!$F:$F,J$5)>0,"PT","") | ... Z12: =IF(COUNTIFS(EmployeeData!$A:$A,$A12,EmployeeData!$F:$F,Z$5)>0,"PT","") | AA12: FH | AB12: =IF(COUNTIFS(EmployeeData!$A:$A,$A12,EmployeeData!$F:$F,AB$5)>0,"PT","") | AC12: =IF(COUNTIFS(EmployeeData!$A:$A,$A12,EmployeeData!$F:$F,AC$5)>0,"PT","") | AD12: =IF(COUNTIFS(EmployeeData!$A:$A,$A12,EmployeeData!$F:$F,AD$5)>0,"PT","") | AE12: =IF(COUNTIFS(EmployeeData!$A:$A,$A12,EmployeeData!$F:$F,AE$5)>0,"PT","") | AF12: =IF(COUNTIFS(EmployeeData!$A:$A,$A12,EmployeeData!$F:$F,AF$5)>0,"PT","") | AG12: =(COUNTIF(B12:AF12,"PT")*1)+(COUNTIF(B12:AF12,"H1")*0.5)+(COUNTIF(B12:AF12,"T")*0)+(COUNTIF(B12:AF12,"R")*0)+(COUNTIF(B12:AF12,"S")*1)+(COUNTIF(B12:AF12,"C")*1)+(COUNTIF(B12:AF12,"FH")*0)+(COUNTIF(B12:AF12,"MT")*1) -> 2 | AH12: =COUNTIF(B12:AF12,"V")+COUNTIF(B12:AF12,"V1")/2+COUNTIF(B12:AF12,"V2")/2 -> 0 | AI12: =COUNTIF(B12:AF12,"S")+COUNTIF(B12:AF12,"S1")/2+COUNTIF(B12:AF12,"S2")/2 -> 0 | AJ12: =COUNTIF(B12:AF12,"M") -> 0 | AK12: =COUNTIF(B12:AF12,"U") -> 0
A13: Rachana, Golla | B13: FH | C13: =IF(COUNTIFS(EmployeeData!$A:$A,$A13,EmployeeData!$F:$F,C$5)>0,"PT","") | D13: =IF(COUNTIFS(EmployeeData!$A:$A,$A13,EmployeeData!$F:$F,D$5)>0,"PT","") | E13: =IF(COUNTIFS(EmployeeData!$A:$A,$A13,EmployeeData!$F:$F,E$5)>0,"PT","") | F13: =IF(COUNTIFS(EmployeeData!$A:$A,$A13,EmployeeData!$F:$F,F$5)>0,"PT","") | G13: =IF(COUNTIFS(EmployeeData!$A:$A,$A13,EmployeeData!$F:$F,G$5)>0,"PT","") | H13: =IF(COUNTIFS(EmployeeData!$A:$A,$A13,EmployeeData!$F:$F,H$5)>0,"PT","") | I13: =IF(COUNTIFS(EmployeeData!$A:$A,$A13,EmployeeData!$F:$F,I$5)>0,"PT","") | J13: =IF(COUNTIFS(EmployeeData!$A:$A,$A13,EmployeeData!$F:$F,J$5)>0,"PT","") | ... Z13: =IF(COUNTIFS(EmployeeData!$A:$A,$A13,EmployeeData!$F:$F,Z$5)>0,"PT","") | AA13: FH | AB13: =IF(COUNTIFS(EmployeeData!$A:$A,$A13,EmployeeData!$F:$F,AB$5)>0,"PT","") | AC13: =IF(COUNTIFS(EmployeeData!$A:$A,$A13,EmployeeData!$F:$F,AC$5)>0,"PT","") | AD13: =IF(COUNTIFS(EmployeeData!$A:$A,$A13,EmployeeData!$F:$F,AD$5)>0,"PT","") | AE13: =IF(COUNTIFS(EmployeeData!$A:$A,$A13,EmployeeData!$F:$F,AE$5)>0,"PT","") | AF13: =IF(COUNTIFS(EmployeeData!$A:$A,$A13,EmployeeData!$F:$F,AF$5)>0,"PT","") | AG13: =(COUNTIF(B13:AF13,"PT")*1)+(COUNTIF(B13:AF13,"H1")*0.5)+(COUNTIF(B13:AF13,"T")*0)+(COUNTIF(B13:AF13,"R")*0)+(COUNTIF(B13:AF13,"S")*1)+(COUNTIF(B13:AF13,"C")*1)+(COUNTIF(B13:AF13,"FH")*0)+(COUNTIF(B13:AF13,"MT")*1) -> 0 | AH13: =COUNTIF(B13:AF13,"V")+COUNTIF(B13:AF13,"V1")/2+COUNTIF(B13:AF13,"V2")/2 -> 0 | AI13: =COUNTIF(B13:AF13,"S")+COUNTIF(B13:AF13,"S1")/2+COUNTIF(B13:AF13,"S2")/2 -> 0 | AJ13: =COUNTIF(B13:AF13,"M") -> 0 | AK13: =COUNTIF(B13:AF13,"U") -> 0
A14: Parth Zalavadia | B14: FH | C14: =IF(COUNTIFS(EmployeeData!$A:$A,$A14,EmployeeData!$F:$F,C$5)>0,"PT","") | D14: =IF(COUNTIFS(EmployeeData!$A:$A,$A14,EmployeeData!$F:$F,D$5)>0,"PT","") | E14: =IF(COUNTIFS(EmployeeData!$A:$A,$A14,EmployeeData!$F:$F,E$5)>0,"PT","") | F14: =IF(COUNTIFS(EmployeeData!$A:$A,$A14,EmployeeData!$F:$F,F$5)>0,"PT","") | G14: =IF(COUNTIFS(EmployeeData!$A:$A,$A14,EmployeeData!$F:$F,G$5)>0,"PT","") | H14: =IF(COUNTIFS(EmployeeData!$A:$A,$A14,EmployeeData!$F:$F,H$5)>0,"PT","") | I14: =IF(COUNTIFS(EmployeeData!$A:$A,$A14,EmployeeData!$F:$F,I$5)>0,"PT","") | J14: =IF(COUNTIFS(EmployeeData!$A:$A,$A14,EmployeeData!$F:$F,J$5)>0,"PT","") | ... Z14: =IF(COUNTIFS(EmployeeData!$A:$A,$A14,EmployeeData!$F:$F,Z$5)>0,"PT","") | AA14: FH | AB14: =IF(COUNTIFS(EmployeeData!$A:$A,$A14,EmployeeData!$F:$F,AB$5)>0,"PT","") | AC14: =IF(COUNTIFS(EmployeeData!$A:$A,$A14,EmployeeData!$F:$F,AC$5)>0,"PT","") | AD14: =IF(COUNTIFS(EmployeeData!$A:$A,$A14,EmployeeData!$F:$F,AD$5)>0,"PT","") | AE14: =IF(COUNTIFS(EmployeeData!$A:$A,$A14,EmployeeData!$F:$F,AE$5)>0,"PT","") | AF14: =IF(COUNTIFS(EmployeeData!$A:$A,$A14,EmployeeData!$F:$F,AF$5)>0,"PT","") | AG14: =(COUNTIF(B14:AF14,"PT")*1)+(COUNTIF(B14:AF14,"H1")*0.5)+(COUNTIF(B14:AF14,"T")*0)+(COUNTIF(B14:AF14,"R")*0)+(COUNTIF(B14:AF14,"S")*1)+(COUNTIF(B14:AF14,"C")*1)+(COUNTIF(B14:AF14,"FH")*0)+(COUNTIF(B14:AF14,"MT")*1) -> 0 | AH14: =COUNTIF(B14:AF14,"V")+COUNTIF(B14:AF14,"V1")/2+COUNTIF(B14:AF14,"V2")/2 -> 0 | AI14: =COUNTIF(B14:AF14,"S")+COUNTIF(B14:AF14,"S1")/2+COUNTIF(B14:AF14,"S2")/2 -> 0 | AJ14: =COUNTIF(B14:AF14,"M") -> 0 | AK14: =COUNTIF(B14:AF14,"U") -> 0
A15: Harshit Malpani | B15: FH | C15: =IF(COUNTIFS(EmployeeData!$A:$A,$A15,EmployeeData!$F:$F,C$5)>0,"PT","") | D15: =IF(COUNTIFS(EmployeeData!$A:$A,$A15,EmployeeData!$F:$F,D$5)>0,"PT","") | E15: =IF(COUNTIFS(EmployeeData!$A:$A,$A15,EmployeeData!$F:$F,E$5)>0,"PT","") | F15: =IF(COUNTIFS(EmployeeData!$A:$A,$A15,EmployeeData!$F:$F,F$5)>0,"PT","") | G15: =IF(COUNTIFS(EmployeeData!$A:$A,$A15,EmployeeData!$F:$F,G$5)>0,"PT","") | H15: =IF(COUNTIFS(EmployeeData!$A:$A,$A15,EmployeeData!$F:$F,H$5)>0,"PT","") | I15: =IF(COUNTIFS(EmployeeData!$A:$A,$A15,EmployeeData!$F:$F,I$5)>0,"PT","") | J15: =IF(COUNTIFS(EmployeeData!$A:$A,$A15,EmployeeData!$F:$F,J$5)>0,"PT","") | ... Z15: =IF(COUNTIFS(EmployeeData!$A:$A,$A15,EmployeeData!$F:$F,Z$5)>0,"PT","") | AA15: FH | AB15: =IF(COUNTIFS(EmployeeData!$A:$A,$A15,EmployeeData!$F:$F,AB$5)>0,"PT","") | AC15: =IF(COUNTIFS(EmployeeData!$A:$A,$A15,EmployeeData!$F:$F,AC$5)>0,"PT","") | AD15: =IF(COUNTIFS(EmployeeData!$A:$A,$A15,EmployeeData!$F:$F,AD$5)>0,"PT","") | AE15: =IF(COUNTIFS(EmployeeData!$A:$A,$A15,EmployeeData!$F:$F,AE$5)>0,"PT","") | AF15: =IF(COUNTIFS(EmployeeData!$A:$A,$A15,EmployeeData!$F:$F,AF$5)>0,"PT","") | AG15: =(COUNTIF(B15:AF15,"PT")*1)+(COUNTIF(B15:AF15,"H1")*0.5)+(COUNTIF(B15:AF15,"T")*0)+(COUNTIF(B15:AF15,"R")*0)+(COUNTIF(B15:AF15,"S")*1)+(COUNTIF(B15:AF15,"C")*1)+(COUNTIF(B15:AF15,"FH")*0)+(COUNTIF(B15:AF15,"MT")*1) -> 1 | AH15: =COUNTIF(B15:AF15,"V")+COUNTIF(B15:AF15,"V1")/2+COUNTIF(B15:AF15,"V2")/2 -> 0 | AI15: =COUNTIF(B15:AF15,"S")+COUNTIF(B15:AF15,"S1")/2+COUNTIF(B15:AF15,"S2")/2 -> 0 | AJ15: =COUNTIF(B15:AF15,"M") -> 0 | AK15: =COUNTIF(B15:AF15,"U") -> 0
A16: Friendsis Rai | B16: FH | C16: =IF(COUNTIFS(EmployeeData!$A:$A,$A16,EmployeeData!$F:$F,C$5)>0,"PT","") | D16: =IF(COUNTIFS(EmployeeData!$A:$A,$A16,EmployeeData!$F:$F,D$5)>0,"PT","") | E16: =IF(COUNTIFS(EmployeeData!$A:$A,$A16,EmployeeData!$F:$F,E$5)>0,"PT","") | F16: =IF(COUNTIFS(EmployeeData!$A:$A,$A16,EmployeeData!$F:$F,F$5)>0,"PT","") | G16: =IF(COUNTIFS(EmployeeData!$A:$A,$A16,EmployeeData!$F:$F,G$5)>0,"PT","") | H16: =IF(COUNTIFS(EmployeeData!$A:$A,$A16,EmployeeData!$F:$F,H$5)>0,"PT","") | I16: =IF(COUNTIFS(EmployeeData!$A:$A,$A16,EmployeeData!$F:$F,I$5)>0,"PT","") | J16: =IF(COUNTIFS(EmployeeData!$A:$A,$A16,EmployeeData!$F:$F,J$5)>0,"PT","") | ... Z16: =IF(COUNTIFS(EmployeeData!$A:$A,$A16,EmployeeData!$F:$F,Z$5)>0,"PT","") | AA16: FH | AB16: =IF(COUNTIFS(EmployeeData!$A:$A,$A16,EmployeeData!$F:$F,AB$5)>0,"PT","") | AC16: =IF(COUNTIFS(EmployeeData!$A:$A,$A16,EmployeeData!$F:$F,AC$5)>0,"PT","") | AD16: =IF(COUNTIFS(EmployeeData!$A:$A,$A16,EmployeeData!$F:$F,AD$5)>0,"PT","") | AE16: =IF(COUNTIFS(EmployeeData!$A:$A,$A16,EmployeeData!$F:$F,AE$5)>0,"PT","") | AF16: =IF(COUNTIFS(EmployeeData!$A:$A,$A16,EmployeeData!$F:$F,AF$5)>0,"PT","") | AG16: =(COUNTIF(B16:AF16,"PT")*1)+(COUNTIF(B16:AF16,"H1")*0.5)+(COUNTIF(B16:AF16,"T")*0)+(COUNTIF(B16:AF16,"R")*0)+(COUNTIF(B16:AF16,"S")*1)+(COUNTIF(B16:AF16,"C")*1)+(COUNTIF(B16:AF16,"FH")*0)+(COUNTIF(B16:AF16,"MT")*1) -> 0 | AH16: =COUNTIF(B16:AF16,"V")+COUNTIF(B16:AF16,"V1")/2+COUNTIF(B16:AF16,"V2")/2 -> 0 | AI16: =COUNTIF(B16:AF16,"S")+COUNTIF(B16:AF16,"S1")/2+COUNTIF(B16:AF16,"S2")/2 -> 0 | AJ16: =COUNTIF(B16:AF16,"M") -> 0 | AK16: =COUNTIF(B16:AF16,"U") -> 0
A17: Divya Maheshwari | B17: FH | C17: =IF(COUNTIFS(EmployeeData!$A:$A,$A17,EmployeeData!$F:$F,C$5)>0,"PT","") | D17: =IF(COUNTIFS(EmployeeData!$A:$A,$A17,EmployeeData!$F:$F,D$5)>0,"PT","") | E17: =IF(COUNTIFS(EmployeeData!$A:$A,$A17,EmployeeData!$F:$F,E$5)>0,"PT","") | F17: =IF(COUNTIFS(EmployeeData!$A:$A,$A17,EmployeeData!$F:$F,F$5)>0,"PT","") | G17: =IF(COUNTIFS(EmployeeData!$A:$A,$A17,EmployeeData!$F:$F,G$5)>0,"PT","") | H17: =IF(COUNTIFS(EmployeeData!$A:$A,$A17,EmployeeData!$F:$F,H$5)>0,"PT","") | I17: =IF(COUNTIFS(EmployeeData!$A:$A,$A17,EmployeeData!$F:$F,I$5)>0,"PT","") | J17: =IF(COUNTIFS(EmployeeData!$A:$A,$A17,EmployeeData!$F:$F,J$5)>0,"PT","") | ... Z17: =IF(COUNTIFS(EmployeeData!$A:$A,$A17,EmployeeData!$F:$F,Z$5)>0,"PT","") | AA17: FH | AB17: =IF(COUNTIFS(EmployeeData!$A:$A,$A17,EmployeeData!$F:$F,AB$5)>0,"PT","") | AC17: =IF(COUNTIFS(EmployeeData!$A:$A,$A17,EmployeeData!$F:$F,AC$5)>0,"PT","") | AD17: =IF(COUNTIFS(EmployeeData!$A:$A,$A17,EmployeeData!$F:$F,AD$5)>0,"PT","") | AE17: =IF(COUNTIFS(EmployeeData!$A:$A,$A17,EmployeeData!$F:$F,AE$5)>0,"PT","") | AF17: =IF(COUNTIFS(EmployeeData!$A:$A,$A17,EmployeeData!$F:$F,AF$5)>0,"PT","") | AG17: =(COUNTIF(B17:AF17,"PT")*1)+(COUNTIF(B17:AF17,"H1")*0.5)+(COUNTIF(B17:AF17,"T")*0)+(COUNTIF(B17:AF17,"R")*0)+(COUNTIF(B17:AF17,"S")*1)+(COUNTIF(B17:AF17,"C")*1)+(COUNTIF(B17:AF17,"FH")*0)+(COUNTIF(B17:AF17,"MT")*1) -> 1 | AH17: =COUNTIF(B17:AF17,"V")+COUNTIF(B17:AF17,"V1")/2+COUNTIF(B17:AF17,"V2")/2 -> 0 | AI17: =COUNTIF(B17:AF17,"S")+COUNTIF(B17:AF17,"S1")/2+COUNTIF(B17:AF17,"S2")/2 -> 0 | AJ17: =COUNTIF(B17:AF17,"M") -> 0 | AK17: =COUNTIF(B17:AF17,"U") -> 0
